Traceback (most recent call last):
  File "D:/UITEST/pythontest/returnconfirm.py", line 104, in <module>
    driver.find_element_by_xpath('//*[@id="app"]/div[4]/div/div[1]/div[2]/div[3]/button[2]').click()
  File "C:\Users\abcd\AppData\Local\Programs\Python\Python36\lib\site-packages\selenium\webdriver\remote\webdriver.py", line 368, in find_element_by_xpath
    return self.find_element(by=By.XPATH, value=xpath)
  File "C:\Users\abcd\AppData\Local\Programs\Python\Python36\lib\site-packages\selenium\webdriver\remote\webdriver.py", line 858, in find_element
    'value': value})['value']
  File "C:\Users\abcd\AppData\Local\Programs\Python\Python36\lib\site-packages\selenium\webdriver\remote\webdriver.py", line 311, in execute
    self.error_handler.check_response(response)
  File "C:\Users\abcd\AppData\Local\Programs\Python\Python36\lib\site-packages\selenium\webdriver\remote\errorhandler.py", line 237, in check_response
    raise exception_class(message, screen, stacktrace)
selenium.common.exceptions.WebDriverException: Message: chrome not reachable
  (Session info: chrome=74.0.3729.169)
  (Driver info: chromedriver=2.43.600210 (68dcf5eebde37173d4027fa8635e332711d2874a),platform=Windows NT 6.3.9600 x86_64)

